<?xml version="1.0" encoding="utf-8"?>
<!-- This URDF was automatically created by SolidWorks to URDF Exporter! Originally created by Stephen Brawner (brawner@gmail.com) 
     Commit Version: 1.6.0-4-g7f85cfe  Build Version: 1.6.7995.38578
     For more information, please see http://wiki.ros.org/sw_urdf_exporter -->
<robot
  name="RobotURDF.SLDASM">
  <link
    name="base_link">
    <inertial>
      <origin
        xyz="-0.046982 0.0003924 -0.084365"
        rpy="0 0 0" />
      <mass
        value="0.22451" />
      <inertia
        ixx="0.00026644"
        ixy="1.0716E-06"
        ixz="5.8747E-05"
        iyy="0.00036767"
        iyz="-5.8394E-07"
        izz="0.00019621" />
    </inertial>
    <visual>
      <origin
        xyz="0 0 0"
        rpy="0 0 0" />
      <geometry>
        <mesh
          filename="package://RobotURDF.SLDASM/meshes/base_link.STL" />
      </geometry>
      <material
        name="">
        <color
          rgba="0 0 128 1" />
      </material>
    </visual>
    <collision>
      <origin
        xyz="0 0 0"
        rpy="0 0 0" />
      <geometry>
        <mesh
          filename="package://RobotURDF.SLDASM/meshes/base_link.STL" />
      </geometry>
    </collision>
  </link>
  <link
    name="link_1">
    <inertial>
      <origin
        xyz="0.064267 -5.2794E-08 -0.002732"
        rpy="0 0 0" />
      <mass
        value="0.031709" />
      <inertia
        ixx="5.3604E-06"
        ixy="-3.8821E-10"
        ixz="1.1495E-07"
        iyy="2.0553E-05"
        iyz="-3.3881E-11"
        izz="1.7224E-05" />
    </inertial>
    <visual>
      <origin
        xyz="0 0 0"
        rpy="0 0 0" />
      <geometry>
        <mesh
          filename="package://RobotURDF.SLDASM/meshes/link_1.STL" />
      </geometry>
      <material
        name="">
        <color
          rgba="0 175 0 1" />
      </material>
    </visual>
    <collision>
      <origin
        xyz="0 0 0"
        rpy="0 0 0" />
      <geometry>
        <mesh
          filename="package://RobotURDF.SLDASM/meshes/link_1.STL" />
      </geometry>
    </collision>
  </link>
  <joint
    name="joint_1"
    type="revolute">
    <origin
      xyz="0 0 0"
      rpy="0 0 0" />
    <parent
      link="base_link" />
    <child
      link="link_1" />
    <axis
      xyz="0 0 1" />
    <limit
      lower="-1.57079632"
      upper="1.57079632"
      effort="0"
      velocity="0" />
  </joint>
  <link
    name="link_2">
    <inertial>
      <origin
        xyz="0.068294 0.00064407 -0.0033292"
        rpy="0 0 0" />
      <mass
        value="0.035007" />
      <inertia
        ixx="5.931E-06"
        ixy="-1.0421E-10"
        ixz="2.9697E-07"
        iyy="2.1337E-05"
        iyz="3.9244E-11"
        izz="1.8561E-05" />
    </inertial>
    <visual>
      <origin
        xyz="0 0 0"
        rpy="0 0 0" />
      <geometry>
        <mesh
          filename="package://RobotURDF.SLDASM/meshes/link_2.STL" />
      </geometry>
      <material
        name="">
        <color
          rgba="220 220 0 1" />
      </material>
    </visual>
    <collision>
      <origin
        xyz="0 0 0"
        rpy="0 0 0" />
      <geometry>
        <mesh
          filename="package://RobotURDF.SLDASM/meshes/link_2.STL" />
      </geometry>
    </collision>
  </link>
  <joint
    name="joint_2"
    type="revolute">
    <origin
      xyz="0.15 0 0"
      rpy="0 0 0" />
    <parent
      link="link_1" />
    <child
      link="link_2" />
    <axis
      xyz="0 0 1" />
    <limit
      lower="-1.57079632"
      upper="1.57079632"
      effort="0"
      velocity="0" />
  </joint>
  <link
    name="link_3">
    <inertial>
      <origin
        xyz="0.043073 5.7658E-07 8.3473E-10"
        rpy="0 0 0" />
      <mass
        value="0.028941" />
      <inertia
        ixx="1.3191E-05"
        ixy="-1.6679E-10"
        ixz="5.0738E-13"
        iyy="2.1452E-05"
        iyz="4.2839E-13"
        izz="9.7312E-06" />
    </inertial>
    <visual>
      <origin
        xyz="0 0 0"
        rpy="0 0 0" />
      <geometry>
        <mesh
          filename="package://RobotURDF.SLDASM/meshes/link_3.STL" />
      </geometry>
      <material
        name="">
        <color
          rgba="200 0 0 1" />
      </material>
    </visual>
    <collision>
      <origin
        xyz="0 0 0"
        rpy="0 0 0" />
      <geometry>
        <mesh
          filename="package://RobotURDF.SLDASM/meshes/link_3.STL" />
      </geometry>
    </collision>
  </link>
  <joint
    name="joint_3"
    type="revolute">
    <origin
      xyz="0.15 0 0"
      rpy="1.57079632 0 0" />
    <parent
      link="link_2" />
    <child
      link="link_3" />
    <axis
      xyz="0 0 1" />
    <limit
      lower="-1.57079632"
      upper="1.57079632"
      effort="0"
      velocity="0" />
  </joint>
</robot>